Workbook

Sheet Parametros
B2: PARÂMETROS — CBHPM 2025/2026
B4: Valor da UCO (R$) | C4: 29.8
B5: Faixa de negociação | C5: ORIGINAL
B7: Valores de porte — Comunicado Oficial CBHPM/AMB 18/10/2025 (INPC 5,10%) — vigência out/2025 a set/2026
B8: Porte | C8: ORIGINAL | D8: FAIXA I | E8: FAIXA II | F8: FAIXA III
B9: 1A | C9: 26.74 | D9: 28.89 | E9: 33.19 | F9: 33.19
B10: 1B | C10: 53.48 | D10: 57.78 | E10: 71.65 | F10: 91.69
B11: 1C | C11: 80.24 | D11: 86.69 | E11: 116.32 | F11: 131.34
B12: 2A | C12: 107 | D12: 115.59 | E12: 165.8 | F12: 194.63
B13: 2B | C13: 141.05 | D13: 152.38 | E13: 236.9 | F13: 306.3
B14: 2C | C14: 166.92 | D14: 209.42 | E14: 293.78 | F14: 417.59
B15: 3A | C15: 228.07 | D15: 294.7 | E15: 427.97 | F15: 598.27
B16: 3B | C16: 291.5 | D16: 381.79 | E16: 562.41 | F16: 778.96
B17: 3C | C17: 333.81 | D17: 451.99 | E17: 688.38 | F17: 959.65
B18: 4A | C18: 397.28 | D18: 539.11 | E18: 822.81 | F18: 1140.34
B19: 4B | C19: 434.89 | D19: 605.55 | E19: 946.9 | F19: 1321.03
B20: 4C | C20: 491.33 | D20: 687.05 | E20: 1078.52 | F20: 1501.71
... B50: 14C | C50: 6922.36 | D50: 6922.36 | E50: 6922.36 | F50: 6922.36

Sheet Tabela CBHPM
B2: TOTAL QUALITY MEDICINA DIAGNÓSTICA — TABELA DE EXAMES · REFERENCIAL CBHPM
B3: CBHPM 2018 (códigos/portes/UCO) · Valores de porte 2025/2026 (AMB, INPC 5,10%) · UCO = R$ 29,80
B4: Valor Porte e Total recalculam ao alterar a UCO ou a Faixa na aba "Parametros" (células amarelas).
B6: TOMOGRAFIA COMPUTADORIZADA MULTISLICE
B7: Código CBHPM | C7: Exame | D7: Porte | E7: Valor Porte (R$) | F7: Custo Oper. (UCO) | G7: Custo Oper. (R$) | H7: Filme (m²) | I7: TOTAL CBHPM (R$) | J7: Observações
B8: 4.10.01.01-0 | C8: TC - Crânio ou sela túrcica ou órbitas | D8: 3B | E8: =1*INDEX(Parametros!$C$9:$F$50,MATCH("3B",Parametros!$B$9:$B$50,0),MATCH(Parametros!$C$5,Parametros!$C$8:$F$8,0)) -> 291.5 | F8: 19.1 | G8: =F8*Parametros!$C$4 -> 569.18 | H8: 1 | I8: =E8+G8 -> 860.68
B9: 4.10.01.03-6 | C9: TC - Face ou seios da face | D9: 3B | E9: =1*INDEX(Parametros!$C$9:$F$50,MATCH("3B",Parametros!$B$9:$B$50,0),MATCH(Parametros!$C$5,Parametros!$C$8:$F$8,0)) -> 291.5 | F9: 22.38 | G9: =F9*Parametros!$C$4 -> 666.924 | H9: 1 | I9: =E9+G9 -> 958.424
B10: 4.10.01.06-0 | C10: TC - Pescoço (partes moles, laringe, tireoide, faringe e glândulas salivares) | D10: 3B | E10: =1*INDEX(Parametros!$C$9:$F$50,MATCH("3B",Parametros!$B$9:$B$50,0),MATCH(Parametros!$C$5,Parametros!$C$8:$F$8,0)) -> 291.5 | F10: 22.38 | G10: =F10*Parametros!$C$4 -> 666.924 | H10: 1.5 | I10: =E10+G10 -> 958.424
B11: 4.10.01.07-9 | C11: TC - Tórax | D11: 3B | E11: =1*INDEX(Parametros!$C$9:$F$50,MATCH("3B",Parametros!$B$9:$B$50,0),MATCH(Parametros!$C$5,Parametros!$C$8:$F$8,0)) -> 291.5 | F11: 22.38 | G11: =F11*Parametros!$C$4 -> 666.924 | H11: 1.5 | I11: =E11+G11 -> 958.424
B12: 4.10.01.10-9 | C12: TC - Abdome superior | D12: 3B | E12: =1*INDEX(Parametros!$C$9:$F$50,MATCH("3B",Parametros!$B$9:$B$50,0),MATCH(Parametros!$C$5,Parametros!$C$8:$F$8,0)) -> 291.5 | F12: 22.38 | G12: =F12*Parametros!$C$4 -> 666.924 | H12: 1.5 | I12: =E12+G12 -> 958.424
B13: 4.10.01.09-5 | C13: TC - Abdome total (abdome superior, pelve e retroperitônio) | D13: 3C | E13: =1*INDEX(Parametros!$C$9:$F$50,MATCH("3C",Parametros!$B$9:$B$50,0),MATCH(Parametros!$C$5,Parametros!$C$8:$F$8,0)) -> 333.81 | F13: 37.45 | G13: =F13*Parametros!$C$4 -> 1116.01 | H13: 2.5 | I13: =E13+G13 -> 1449.82
B14: 4.10.01.11-7 | C14: TC - Pelve ou bacia | D14: 3A | E14: =1*INDEX(Parametros!$C$9:$F$50,MATCH("3A",Parametros!$B$9:$B$50,0),MATCH(Parametros!$C$5,Parametros!$C$8:$F$8,0)) -> 228.07 | F14: 22.38 | G14: =F14*Parametros!$C$4 -> 666.924 | H14: 1.5 | I14: =E14+G14 -> 894.994
B15: 4.10.01.12-5 | C15: TC - Coluna cervical (código único: cervical ou dorsal ou lombo-sacra até 3 segmentos) | D15: 3A | E15: =1*INDEX(Parametros!$C$9:$F$50,MATCH("3A",Parametros!$B$9:$B$50,0),MATCH(Parametros!$C$5,Parametros!$C$8:$F$8,0)) -> 228.07 | F15: 18.2 | G15: =F15*Parametros!$C$4 -> 542.36 | H15: 1 | I15: =E15+G15 -> 770.43 | J15: Código único p/ cervical, dorsal ou lombo-sacra (até 3 segmentos)
B16: 4.10.01.12-5 | C16: TC - Coluna dorsal (código único: cervical ou dorsal ou lombo-sacra até 3 segmentos) | D16: 3A | E16: =1*INDEX(Parametros!$C$9:$F$50,MATCH("3A",Parametros!$B$9:$B$50,0),MATCH(Parametros!$C$5,Parametros!$C$8:$F$8,0)) -> 228.07 | F16: 18.2 | G16: =F16*Parametros!$C$4 -> 542.36 | H16: 1 | I16: =E16+G16 -> 770.43 | J16: Código único p/ cervical, dorsal ou lombo-sacra (até 3 segmentos)
B17: 4.10.01.12-5 | C17: TC - Coluna lombo-sacra (código único: cervical ou dorsal ou lombo-sacra até 3 segmentos) | D17: 3A | E17: =1*INDEX(Parametros!$C$9:$F$50,MATCH("3A",Parametros!$B$9:$B$50,0),MATCH(Parametros!$C$5,Parametros!$C$8:$F$8,0)) -> 228.07 | F17: 18.2 | G17: =F17*Parametros!$C$4 -> 542.36 | H17: 1 | I17: =E17+G17 -> 770.43 | J17: Código único p/ cervical, dorsal ou lombo-sacra (até 3 segmentos)
B18: 4.10.01.13-3 | C18: TC - Coluna - segmento adicional | D18: 1C | E18: =1*INDEX(Parametros!$C$9:$F$50,MATCH("1C",Parametros!$B$9:$B$50,0),MATCH(Parametros!$C$5,Parametros!$C$8:$F$8,0)) -> 80.24 | F18: 4.28 | G18: =F18*Parametros!$C$4 -> 127.544 | H18: 0.5 | I18: =E18+G18 -> 207.784 | J18: Cobrar por segmento adicional de coluna
B19: 4.10.01.14-1 | C19: TC - Articulação (esternoclavicular ou ombro ou cotovelo ou punho ou sacroilíacas ou coxofemoral ou joelho ou tornozelo) - unilateral | D19: 3A | E19: =1*INDEX(Parametros!$C$9:$F$50,MATCH("3A",Parametros!$B$9:$B$50,0),MATCH(Parametros!$C$5,Parametros!$C$8:$F$8,0)) -> 228.07 | F19: 22.38 | G19: =F19*Parametros!$C$4 -> 666.924 | H19: 1.5 | I19: =E19+G19 -> 894.994
B20: 4.10.01.15-0 | C20: TC - Segmento apendicular (braço ou antebraço ou mão ou coxa ou perna ou pé) - unilateral | D20: 3A | E20: =1*INDEX(Parametros!$C$9:$F$50,MATCH("3A",Parametros!$B$9:$B$50,0),MATCH(Parametros!$C$5,Parametros!$C$8:$F$8,0)) -> 228.07 | F20: 22.38 | G20: =F20*Parametros!$C$4 -> 666.924 | H20: 1.5 | I20: =E20+G20 -> 894.994
C21: Contraste em TC: reembolsado à parte (obs. 4.10.99.00-1) — sem % fixo no porte. TC 'com contraste' = mesmo código + reembolso do contraste.
B23: RAIO-X DIGITAL
B24: Código CBHPM | C24: Exame | D24: Porte | E24: Valor Porte (R$) | F24: Custo Oper. (UCO) | G24: Custo Oper. (R$) | H24: Filme (m²) | I24: TOTAL CBHPM (R$) | J24: Observações
B25: 4.08.05.01-8 | C25: RX - Tórax - 1 incidência | D25: 1B | E25: =1*INDEX(Parametros!$C$9:$F$50,MATCH("1B",Parametros!$B$9:$B$50,0),MATCH(Parametros!$C$5,Parametros!$C$8:$F$8,0)) -> 53.48 | F25: 0.83 | G25: =F25*Parametros!$C$4 -> 24.734 | H25: 0.154 | I25: =E25+G25 -> 78.214
B26: 4.08.05.02-6 | C26: RX - Tórax - 2 incidências | D26: 1B | E26: =1*INDEX(Parametros!$C$9:$F$50,MATCH("1B",Parametros!$B$9:$B$50,0),MATCH(Parametros!$C$5,Parametros!$C$8:$F$8,0)) -> 53.48 | F26: 1.18 | G26: =F26*Parametros!$C$4 -> 35.164 | H26: 0.308 | I26: =E26+G26 -> 88.644
B27: 4.08.02.01-9 | C27: RX - Coluna cervical - 3 incidências | D27: 1B | E27: =1*INDEX(Parametros!$C$9:$F$50,MATCH("1B",Parametros!$B$9:$B$50,0),MATCH(Parametros!$C$5,Parametros!$C$8:$F$8,0)) -> 53.48 | F27: 1.31 | G27: =F27*Parametros!$C$4 -> 39.038 | H27: 0.1296 | I27: =E27+G27 -> 92.518
B28: 4.08.02.03-5 | C28: RX - Coluna dorsal - 2 incidências | D28: 1B | E28: =1*INDEX(Parametros!$C$9:$F$50,MATCH("1B",Parametros!$B$9:$B$50,0),MATCH(Parametros!$C$5,Parametros!$C$8:$F$8,0)) -> 53.48 | F28: 1.4 | G28: =F28*Parametros!$C$4 -> 41.72 | H28: 0.24 | I28: =E28+G28 -> 95.2
B29: 4.08.02.05-1 | C29: RX - Coluna lombo-sacra - 3 incidências | D29: 1B | E29: =1*INDEX(Parametros!$C$9:$F$50,MATCH("1B",Parametros!$B$9:$B$50,0),MATCH(Parametros!$C$5,Parametros!$C$8:$F$8,0)) -> 53.48 | F29: 1.4 | G29: =F29*Parametros!$C$4 -> 41.72 | H29: 0.312 | I29: =E29+G29 -> 95.2
B30: 4.08.01.01-2 | C30: RX - Crânio - 2 incidências | D30: 1B | E30: =1*INDEX(Parametros!$C$9:$F$50,MATCH("1B",Parametros!$B$9:$B$50,0),MATCH(Parametros!$C$5,Parametros!$C$8:$F$8,0)) -> 53.48 | F30: 1.31 | G30: =F30*Parametros!$C$4 -> 39.038 | H30: 0.144 | I30: =E30+G30 -> 92.518
B31: 4.08.01.06-3 | C31: RX - Seios da face | D31: 1B | E31: =1*INDEX(Parametros!$C$9:$F$50,MATCH("1B",Parametros!$B$9:$B$50,0),MATCH(Parametros!$C$5,Parametros!$C$8:$F$8,0)) -> 53.48 | F31: 1.47 | G31: =F31*Parametros!$C$4 -> 43.806 | H31: 0.1296 | I31: =E31+G31 -> 97.286
B32: 4.08.03.12-0 | C32: RX - Mão ou quirodáctilo | D32: 1B | E32: =1*INDEX(Parametros!$C$9:$F$50,MATCH("1B",Parametros!$B$9:$B$50,0),MATCH(Parametros!$C$5,Parametros!$C$8:$F$8,0)) -> 53.48 | F32: 1.22 | G32: =F32*Parametros!$C$4 -> 36.356 | H32: 0.0864 | I32: =E32+G32 -> 89.836
B33: 4.08.03.11-2 | C33: RX - Punho | D33: 1B | E33: =1*INDEX(Parametros!$C$9:$F$50,MATCH("1B",Parametros!$B$9:$B$50,0),MATCH(Parametros!$C$5,Parametros!$C$8:$F$8,0)) -> 53.48 | F33: 1.22 | G33: =F33*Parametros!$C$4 -> 36.356 | H33: 0.1728 | I33: =E33+G33 -> 89.836
B34: 4.08.04.05-4 | C34: RX - Joelho | D34: 1B | E34: =1*INDEX(Parametros!$C$9:$F$50,MATCH("1B",Parametros!$B$9:$B$50,0),MATCH(Parametros!$C$5,Parametros!$C$8:$F$8,0)) -> 53.48 | F34: 1.22 | G34: =F34*Parametros!$C$4 -> 36.356 | H34: 0.144 | I34: =E34+G34 -> 89.836
B35: 4.08.03.07-4 | C35: RX - Articulação escapuloumeral (ombro) | D35: 1B | E35: =1*INDEX(Parametros!$C$9:$F$50,MATCH("1B",Parametros!$B$9:$B$50,0),MATCH(Parametros!$C$5,Parametros!$C$8:$F$8,0)) -> 53.48 | F35: 1.31 | G35: =F35*Parametros!$C$4 -> 39.038 | H35: 0.0864 | I35: =E35+G35 -> 92.518
B36: 4.08.04.03-8 | C36: RX - Articulação coxofemoral (quadril) | D36: 1B | E36: =1*INDEX(Parametros!$C$9:$F$50,MATCH("1B",Parametros!$B$9:$B$50,0),MATCH(Parametros!$C$5,Parametros!$C$8:$F$8,0)) -> 53.48 | F36: 1.31 | G36: =F36*Parametros!$C$4 -> 39.038 | H36: 0.192 | I36: =E36+G36 -> 92.518
... B40: 4.08.03.13-9 | C40: RX - Mãos e punhos para idade óssea | D40: 1B | E40: =1*INDEX(Parametros!$C$9:$F$50,MATCH("1B",Parametros!$B$9:$B$50,0),MATCH(Parametros!$C$5,Parametros!$C$8:$F$8,0)) -> 53.48 | F40: 1.22 | G40: =F40*Parametros!$C$4 -> 36.356 | H40: 0.072 | I40: =E40+G40 -> 89.836
B42: MAMOGRAFIA DIGITAL
B43: Código CBHPM | C43: Exame | D43: Porte | E43: Valor Porte (R$) | F43: Custo Oper. (UCO) | G43: Custo Oper. (R$) | H43: Filme (m²) | I43: TOTAL CBHPM (R$) | J43: Observações
B44: 4.08.08.03-3 | C44: Mamografia convencional bilateral | D44: 2C | E44: =1*INDEX(Parametros!$C$9:$F$50,MATCH("2C",Parametros!$B$9:$B$50,0),MATCH(Parametros!$C$5,Parametros!$C$8:$F$8,0)) -> 166.92 | F44: 2.76 | G44: =F44*Parametros!$C$4 -> 82.248 | H44: 1.2 | I44: =E44+G44 -> 249.168
B45: 4.08.08.04-1 | C45: Mamografia digital bilateral | D45: 2C | E45: =1*INDEX(Parametros!$C$9:$F$50,MATCH("2C",Parametros!$B$9:$B$50,0),MATCH(Parametros!$C$5,Parametros!$C$8:$F$8,0)) -> 166.92 | F45: 6.48 | G45: =F45*Parametros!$C$4 -> 193.104 | H45: 1.2 | I45: =E45+G45 -> 360.024 | J45: Código próprio de mamografia digital
B47: ULTRASSONOGRAFIA GERAL E DOPPLER
B48: Código CBHPM | C48: Exame | D48: Porte | E48: Valor Porte (R$) | F48: Custo Oper. (UCO) | G48: Custo Oper. (R$) | H48: Filme (m²) | I48: TOTAL CBHPM (R$) | J48: Observações
...

Sheet Leia-me
B2: LEIA-ME — TABELA DE EXAMES CBHPM · TOTAL QUALITY MEDICINA DIAGNÓSTICA
B4: Como usar
B5: • As células AMARELAS na aba Parametros são editáveis: valor da UCO (C4) e Faixa de negociação (C5, lista suspensa: ORIGINAL, FAIXA I, II, III).
B6: • As colunas 'Valor Porte', 'Custo Oper. (R$)' e 'TOTAL CBHPM' recalculam automaticamente a partir desses parâmetros.
B7: • TOTAL CBHPM = Valor do Porte (honorário) + Custo Operacional (nº de UCO × valor da UCO). O filme (m²) é informativo e NÃO está somado (clínica digital).
B8: • Exemplo de leitura: US Abdome total = porte 3A (R$ 228,07 na faixa Original) + 5,85 UCO × R$ 29,80 = R$ 402,40.
B10: Fontes (verificadas em 31/07/2026)
B11: • Códigos, portes, nº de UCO e filme: CBHPM 2018 — PDF do acervo no Google Drive (2018-cbhpm-portal-do-faturamento-hospitalar.pdf). 100% extraído do documento, sem estimativas.
B12: • Valores de porte e UCO R$ 29,80: Comunicado Oficial CBHPM/AMB de 18/10/2025 (INPC 5,10%; vigência out/2025–set/2026), com as 4 faixas de negociação.
B14: Avisos importantes
B15: • CBHPM é REFERENCIAL: o valor pago por cada operadora segue o CONTRATO (edição contratada + deságio/ágio + UCO contratual). Para particular, a clínica define o preço final.
B16: • A edição-base vigente da CBHPM é a de 2022 (com RNs até a 071/2026). Esta tabela usa a edição 2018 (acervo disponível) — pode haver diferenças pontuais de porte/UCO em relação à 2022.
... B21: • Laboratório: portes expressos como fração do porte 1A (padrão CBHPM). O catálogo de +3.000 exames segue a mesma lógica — esta aba traz os 25 mais comuns.
